#VRML_SIM R2022b utf8
# license: Apache License 2.0
# license url: http://www.apache.org/licenses/LICENSE-2.0
# This is a proto file for Webots for the Jetracer
# Extracted from: /home/navid/01_my_packages/Pichierri_05/ChoirJet/src/choirjet_examples/resource/jetracer.urdf

PROTO Jetracer [
  field  SFVec3f     translation     0 0 0
  field  SFRotation  rotation        0 0 1 0
  field  SFString    name            "Jetracer"  # Is `Robot.name`.
  field  SFString    controller      "void"      # Is `Robot.controller`.
  field  MFString    controllerArgs  []          # Is `Robot.controllerArgs`.
  field  SFString    customData      ""          # Is `Robot.customData`.
  field  SFBool      supervisor      FALSE       # Is `Robot.supervisor`.
  field  SFBool      synchronization TRUE        # Is `Robot.synchronization`.
  field  SFBool      selfCollision   FALSE       # Is `Robot.selfCollision`.
  field  SFBool      staticBase      TRUE        # Defines if the robot base should be pinned to the static environment.
  field  MFNode      toolSlot        []          # Extend the robot with new nodes at the end of the arm.
]
{
  Robot {
    translation IS translation
    rotation IS rotation
    controller IS controller
    controllerArgs IS controllerArgs
    customData IS customData
    supervisor IS supervisor
    synchronization IS synchronization
    selfCollision IS selfCollision
    children [
      Transform {
        translation 0.106000 0.000000 0.047000
        children [
          Shape {
            appearance PBRAppearance {
              baseColor 0.500000 0.500000 0.500000
              roughness 1.000000
              metalness 0
            }
            geometry Box {
               size 0.255000 0.110000 0.090000
            }
          }
        ]
      }
      Solid {
        translation 0.190000 0.000000 0.114000
        rotation 0.000000 0.000000 1.000000 3.141590
        children [
          Transform {
            translation 0.014000 0.000000 -0.014000
            rotation 0.577351 -0.577348 -0.577351 2.094405
            children [
              Shape {
                appearance PBRAppearance {
                  baseColor 0.500000 0.500000 0.500000
                  roughness 1.000000
                  metalness 0
                }
                geometry Box {
                   size 0.070000 0.010000 0.100000
                }
              }
            ]
          }
          Shape {
            appearance PBRAppearance {
              baseColor 0.500000 0.500000 0.500000
              roughness 1.000000
              metalness 0
            }
            geometry Cylinder {
              radius 0.032
              height 0.021
            }
          }
        ]
      }
          Solid {
            translation 0.035000 0.024500 -0.010500
            rotation 0.000000 1.000000 0.000000 1.570787
            children [
              Transform {
                translation 0.010000 0.000000 0.000000
                rotation -0.000000 1.000000 -0.000000 1.570800
                children [
                  Shape {
                    appearance PBRAppearance {
                      baseColor 0.500000 0.500000 0.500000
                      roughness 1.000000
                      metalness 0
                    }
                    geometry Cylinder {
                      radius 0.0015
                      height 0.02
                    }
                  }
                ]
              }
              Transform {
                translation -0.001500 0.000000 0.000000
                rotation -0.000000 1.000000 -0.000000 1.570800
                children [
                  Shape {
                    appearance PBRAppearance {
                      baseColor 0.500000 0.500000 0.500000
                      roughness 1.000000
                      metalness 0
                    }
                    geometry Cylinder {
                      radius 0.0025
                      height 0.003
                    }
                  }
                ]
              }
            ]
            name "screw3"
            boundingObject Group {
              children [
                Cylinder {
                  radius 0.0015
                  height 0.02
                }
                Cylinder {
                  radius 0.0025
                  height 0.003
                }
              ]
            }
            physics Physics {
            }
          }
          Solid {
            translation 0.035000 0.024500 -0.010500
            rotation 0.000000 1.000000 0.000000 1.570787
            children [
              Transform {
                translation 0.010000 0.000000 0.000000
                rotation -0.000000 1.000000 -0.000000 1.570800
                children [
                  Shape {
                    appearance PBRAppearance {
                      baseColor 0.500000 0.500000 0.500000
                      roughness 1.000000
                      metalness 0
                    }
                    geometry Cylinder {
                      radius 0.0015
                      height 0.02
                    }
                  }
                ]
              }
              Transform {
                translation -0.001500 0.000000 0.000000
                rotation -0.000000 1.000000 -0.000000 1.570800
                children [
                  Shape {
                    appearance PBRAppearance {
                      baseColor 0.500000 0.500000 0.500000
                      roughness 1.000000
                      metalness 0
                    }
                    geometry Cylinder {
                      radius 0.0025
                      height 0.003
                    }
                  }
                ]
              }
            ]
            name "screw2"
            boundingObject Group {
              children [
                Cylinder {
                  radius 0.0015
                  height 0.02
                }
                Cylinder {
                  radius 0.0025
                  height 0.003
                }
              ]
            }
            physics Physics {
            }
          }
          Solid {
            translation 0.035000 0.024500 -0.010500
            rotation 0.000000 1.000000 0.000000 1.570787
            children [
              Transform {
                translation 0.010000 0.000000 0.000000
                rotation -0.000000 1.000000 -0.000000 1.570800
                children [
                  Shape {
                    appearance PBRAppearance {
                      baseColor 0.500000 0.500000 0.500000
                      roughness 1.000000
                      metalness 0
                    }
                    geometry Cylinder {
                      radius 0.0015
                      height 0.02
                    }
                  }
                ]
              }
              Transform {
                translation -0.001500 0.000000 0.000000
                rotation -0.000000 1.000000 -0.000000 1.570800
                children [
                  Shape {
                    appearance PBRAppearance {
                      baseColor 0.500000 0.500000 0.500000
                      roughness 1.000000
                      metalness 0
                    }
                    geometry Cylinder {
                      radius 0.0025
                      height 0.003
                    }
                  }
                ]
              }
            ]
            name "screw1"
            boundingObject Group {
              children [
                Cylinder {
                  radius 0.0015
                  height 0.02
                }
                Cylinder {
                  radius 0.0025
                  height 0.003
                }
              ]
            }
            physics Physics {
            }
          }
          Solid {
            translation 0.035000 0.024500 -0.010500
            rotation 0.000000 1.000000 0.000000 1.570787
            children [
              Transform {
                translation 0.010000 0.000000 0.000000
                rotation -0.000000 1.000000 -0.000000 1.570800
                children [
                  Shape {
                    appearance PBRAppearance {
                      baseColor 0.500000 0.500000 0.500000
                      roughness 1.000000
                      metalness 0
                    }
                    geometry Cylinder {
                      radius 0.0015
                      height 0.02
                    }
                  }
                ]
              }
              Transform {
                translation -0.001500 0.000000 0.000000
                rotation -0.000000 1.000000 -0.000000 1.570800
                children [
                  Shape {
                    appearance PBRAppearance {
                      baseColor 0.500000 0.500000 0.500000
                      roughness 1.000000
                      metalness 0
                    }
                    geometry Cylinder {
                      radius 0.0025
                      height 0.003
                    }
                  }
                ]
              }
            ]
            name "screw0"
            boundingObject Group {
              children [
                Cylinder {
                  radius 0.0015
                  height 0.02
                }
                Cylinder {
                  radius 0.0025
                  height 0.003
                }
              ]
            }
            physics Physics {
            }
          }
        ]
        name "lidar"
        boundingObject Group {
          children [
            Box {
               size 0.070000 0.010000 0.100000
            }
            Cylinder {
              radius 0.032
              height 0.021
            }
          ]
        }
        physics Physics {
        }
      }
      HingeJoint {
        jointParameters HingeJointParameters {
          axis -0.000004 1.000000 0.000000
          anchor 0.000000 -0.070000 0.000000
        }
        device [
          RotationalMotor {
            name "right_rear_wheel"
            maxVelocity 2173.91
            maxTorque 100000000.0
          }
          PositionSensor {
            name "right_rear_wheel_sensor"
          }
        ]
        endPoint Solid {
          translation 0.000000 -0.070000 0.000000
          rotation 0.000000 0.000000 1.000000 1.570800
          children [
            Transform {
              rotation 0.000000 1.000000 0.000000 1.570796
              children [
                Shape {
                  appearance PBRAppearance {
                    baseColor 0.500000 0.500000 0.500000
                    roughness 1.000000
                    metalness 0
                  }
                  geometry Cylinder {
                    radius 0.023
                    height 0.018
                  }
                }
              ]
            }
          ]
          name "rear right wheel"
          boundingObject Cylinder {
            radius 0.023
            height 0.018
          }
          physics Physics {
          }
        }
      }
      Solid {
        children [
          Transform {
            rotation 0.000000 1.000000 0.000000 1.570796
            children [
              Shape {
                appearance PBRAppearance {
                  baseColor 0.500000 0.500000 0.500000
                  roughness 1.000000
                  metalness 0
                }
                geometry Cylinder {
                  radius 0.023
                  height 0.018
                }
              }
            ]
          }
        ]
        name "rear right wheel"
        boundingObject Cylinder {
          radius 0.023
          height 0.018
        }
        physics Physics {
        }
      }
      HingeJoint {
        jointParameters HingeJointParameters {
          axis 0.000004 1.000000 0.000000
          anchor 0.000000 0.070000 0.000000
        }
        device [
          RotationalMotor {
            name "left_rear_wheel"
            maxVelocity 2173.91
            maxTorque 100000000.0
          }
          PositionSensor {
            name "left_rear_wheel_sensor"
          }
        ]
        endPoint Solid {
          translation 0.000000 0.070000 0.000000
          rotation 0.000000 0.000000 -1.000000 1.570800
          children [
            Transform {
              rotation 0.000000 1.000000 0.000000 1.570796
              children [
                Shape {
                  appearance PBRAppearance {
                    baseColor 0.500000 0.500000 0.500000
                    roughness 1.000000
                    metalness 0
                  }
                  geometry Cylinder {
                    radius 0.023
                    height 0.018
                  }
                }
              ]
            }
          ]
          name "rear left wheel"
          boundingObject Cylinder {
            radius 0.023
            height 0.018
          }
          physics Physics {
          }
        }
      }
      Solid {
        children [
          Transform {
            rotation 0.000000 1.000000 0.000000 1.570796
            children [
              Shape {
                appearance PBRAppearance {
                  baseColor 0.500000 0.500000 0.500000
                  roughness 1.000000
                  metalness 0
                }
                geometry Cylinder {
                  radius 0.023
                  height 0.018
                }
              }
            ]
          }
        ]
        name "rear left wheel"
        boundingObject Cylinder {
          radius 0.023
          height 0.018
        }
        physics Physics {
        }
      }
    ]
    name IS name
    boundingObject Box {
       size 0.255000 0.110000 0.090000
    }
  }
}
